import axios from "axios";
import { API_URL_BACK_END } from "@/utils/constants";

export const getAllAyudasEmpleados = async () => {
  const url = API_URL_BACK_END.replace("#", "ayudasEmpleados");
  try {
    const response = await axios.get(url + "getAll");
    return {
      data: response.data,
      status: response.status,
    };
  } catch (error) {
    if (error.response) {
      return {
        errorMessage: error.response.data.message,
        status: error.response.status,
      };
    } else {
      return {
        errorMessage:
          "Se ha producido un error inesperado. Por favor, inténtalo de nuevo más tarde",
        status: 500,
      };
    }
  }
};

export const saveAyudaEmpleado = async (data) => {
  const url = API_URL_BACK_END.replace("#", "ayudasEmpleados");

  try {
    const formData = {};

    const response = await axios.post(url + "save", formData);
    return {
      data: response.data,
      status: response.status,
    };
  } catch (error) {
    if (error.response) {
      return {
        errorMessage: error.response.data.message,
        status: error.response.status,
      };
    } else {
      return {
        errorMessage:
          "Se ha producido un error inesperado. Por favor, inténtalo de nuevo más tarde",
        status: 500,
      };
    }
  }
};

export const getAyudaEmpleadoById = async (id) => {
  const url = API_URL_BACK_END.replace("#", "ayudasEmpleados");
  try {
    const response = await axios.get(url + "getById/" + id);
    return {
      data: response.data,
      status: response.status,
    };
  } catch (error) {
    if (error.response) {
      return {
        errorMessage: error.response.data.message,
        status: error.response.status,
      };
    } else {
      return {
        errorMessage:
          "Se ha producido un error inesperado. Por favor, inténtalo de nuevo más tarde",
        status: 500,
      };
    }
  }
};

export const updateAyudaEmpleado = async (id, data) => {
  const url = API_URL_BACK_END.replace("#", "ayudasEmpleados");

  try {
    const formData = {};

    const response = await axios.put(url + "update/" + id, formData);
    return {
      data: response.data,
      status: response.status,
    };
  } catch (error) {
    if (error.response) {
      return {
        errorMessage: error.response.data.message,
        status: error.response.status,
      };
    } else {
      return {
        errorMessage:
          "Se ha producido un error inesperado. Por favor, inténtalo de nuevo más tarde",
        status: 500,
      };
    }
  }
};

export const deleteAyudaEmpleado = async (id) => {
  const url = API_URL_BACK_END.replace("#", "ayudasEmpleados");
  try {
    const response = await axios.delete(url + "delete/" + id);
    return {
      data: response.data,
      status: response.status,
    };
  } catch (error) {
    if (error.response) {
      return {
        errorMessage: error.response.data,
        status: error.response.status,
      };
    } else {
      return {
        errorMessage:
          "Se ha producido un error inesperado. Por favor, inténtalo de nuevo más tarde",
        status: 500,
      };
    }
  }
};
